WARNING:FaceDetectionService.get_faces-get_faces:Event save_file was not called before
WARNING:FaceDetectionService.get_faces-get_faces:Event delete_file was not called during method execution
WARNING:FaceDetectionService.get_faces-get_faces:File not deleted
WARNING:FaceDetectionService.get_faces-get_faces:Event save_file was not called before
WARNING:FaceDetectionService.get_faces-get_faces:Event delete_file was not called during method execution
WARNING:FaceDetectionService.get_faces-get_faces:File not deleted
WARNING:FaceDetectionService.get_faces-get_faces:Event save_image was not called before
INFO:werkzeug: * Running on http://127.0.0.1:5000/ (Press CTRL+C to quit)
ERROR:app:Exception on /detection [POST]
Traceback (most recent call last):
  File "C:\Users\Roxanica\AppData\Local\Programs\Python\Python39\lib\site-packages\flask\app.py", line 2073, in wsgi_app
    response = self.full_dispatch_request()
  File "C:\Users\Roxanica\AppData\Local\Programs\Python\Python39\lib\site-packages\flask\app.py", line 1518, in full_dispatch_request
    rv = self.handle_user_exception(e)
  File "C:\Users\Roxanica\AppData\Local\Programs\Python\Python39\lib\site-packages\flask\app.py", line 1516, in full_dispatch_request
    rv = self.dispatch_request()
  File "C:\Users\Roxanica\AppData\Local\Programs\Python\Python39\lib\site-packages\flask\app.py", line 1502, in dispatch_request
    return self.ensure_sync(self.view_functions[rule.endpoint])(**req.view_args)
  File "D:\master\ip\TAIP-2021-2022-PROIECT\face_recognition_module\app.py", line 24, in detection
    result = FaceDetectionService.get_faces("./temp/" + filename)
  File "D:\master\ip\TAIP-2021-2022-PROIECT\face_recognition_module\mop\mop_decorators.py", line 60, in wrapper
    return func(*args, **kwargs)
  File "D:\master\ip\TAIP-2021-2022-PROIECT\face_recognition_module\mop\mop_decorators.py", line 30, in wrapper
    return func(*args, **kwargs)
  File "D:\master\ip\TAIP-2021-2022-PROIECT\face_recognition_module\mop\mop_decorators.py", line 38, in wrapper
    result = func(*args, **kwargs)
  File "D:\master\ip\TAIP-2021-2022-PROIECT\face_recognition_module\mop\mop_decorators.py", line 71, in wrapper
    result = func(*args, **kwargs)
  File "D:\master\ip\TAIP-2021-2022-PROIECT\face_recognition_module\services\face_detection_service.py", line 23, in get_faces
    delete_image(path)
  File "D:\master\ip\TAIP-2021-2022-PROIECT\face_recognition_module\mop\mop_decorators.py", line 90, in wrapper
    return func(*args, **kwargs)
  File "D:\master\ip\TAIP-2021-2022-PROIECT\face_recognition_module\core\utils.py", line 13, in delete_image
    os.remove(os.path.join('temp', filename))
FileNotFoundError: [WinError 3] The system cannot find the path specified: 'temp\\./temp/3086244.jpg'
INFO:werkzeug:127.0.0.1 - - [21/Nov/2021 22:15:14] "[35m[1mPOST /detection HTTP/1.1[0m" 500 -
INFO:werkzeug: * Running on http://127.0.0.1:5000/ (Press CTRL+C to quit)
INFO:werkzeug:127.0.0.1 - - [21/Nov/2021 22:17:58] "POST /detection HTTP/1.1" 200 -
